Workbook

Sheet Dynamic Bet Results
A1: Dynamic Bet Results: every pick emailed under that day's rule
A2: Graded on the line in the email. Only picks that were emailed before the game count; nothing is filled in afterwards.
A4: Total units | C4: Win % | E4: Record | G4: Bets | I4: Waiting on a result
A5: =SUM(F9:F35) | C5: =IFERROR(COUNTIF(G9:G35,"W")/(COUNTIF(G9:G35,"W")+COUNTIF(G9:G35,"L")),"") | E5: =COUNTIF(G9:G35,"W")&"-"&COUNTIF(G9:G35,"L") | G5: =COUNTIF(G9:G35,"W")+COUNTIF(G9:G35,"L") | I5: =COUNTA(B9:B35)-COUNTIF(G9:G35,"W")-COUNTIF(G9:G35,"L")
A8: Date | B8: Matchup | C8: Pick | D8: Line when emailed | E8: Differential | F8: Units | G8: Result | H8: Final score | I8: That day's rule
A9: 46317 | B9: NYR @ TOR | C9: NYR | D9: -112 | E9: 5.83 | F9: =IF(AND(G9<>"W",G9<>"L"),"",IF(G9="W",IF(D9>0,D9/100,1),IF(D9<0,D9/100,-1))) | G9: L | H9: NYR 4, TOR 5 | I9: Bet the pick when it has a line from -192 to +110 and a differential of 23.51 or less; home or away.
A10: 46317 | B10: SJS @ OTT | C10: OTT | D10: -135 | E10: 22.86 | F10: =IF(AND(G10<>"W",G10<>"L"),"",IF(G10="W",IF(D10>0,D10/100,1),IF(D10<0,D10/100,-1))) | G10: L | H10: SJS 6, OTT 2 | I10: Bet the pick when it has a line from -192 to +110 and a differential of 23.51 or less; home or away.
A11: 46317 | B11: FLA @ PIT | C11: PIT | D11: -108 | E11: 4.96 | F11: =IF(AND(G11<>"W",G11<>"L"),"",IF(G11="W",IF(D11>0,D11/100,1),IF(D11<0,D11/100,-1))) | G11: W | H11: FLA 0, PIT 4 | I11: Bet the pick when it has a line from -192 to +110 and a differential of 23.51 or less; home or away.
A12: 46317 | B12: LAK @ NYI | C12: NYI | D12: -105 | E12: 16.97 | F12: =IF(AND(G12<>"W",G12<>"L"),"",IF(G12="W",IF(D12>0,D12/100,1),IF(D12<0,D12/100,-1))) | G12: L | H12: LAK 3, NYI 2 | I12: Bet the pick when it has a line from -192 to +110 and a differential of 23.51 or less; home or away.
A13: 46317 | B13: VGK @ STL | C13: STL | D13: 110 | E13: 13.02 | F13: =IF(AND(G13<>"W",G13<>"L"),"",IF(G13="W",IF(D13>0,D13/100,1),IF(D13<0,D13/100,-1))) | G13: W | H13: VGK 2, STL 6 | I13: Bet the pick when it has a line from -192 to +110 and a differential of 23.51 or less; home or away.
A14: 46317 | B14: CAR @ EDM | C14: CAR | D14: -118 | E14: 19.43 | F14: =IF(AND(G14<>"W",G14<>"L"),"",IF(G14="W",IF(D14>0,D14/100,1),IF(D14<0,D14/100,-1))) | G14: L | H14: CAR 5, EDM 6 | I14: Bet the pick when it has a line from -192 to +110 and a differential of 23.51 or less; home or away.
A15: 46317 | B15: UTA @ SEA | C15: UTA | D15: -170 | E15: 13.21 | F15: =IF(AND(G15<>"W",G15<>"L"),"",IF(G15="W",IF(D15>0,D15/100,1),IF(D15<0,D15/100,-1))) | G15: L | H15: UTA 3, SEA 5 | I15: Bet the pick when it has a line from -192 to +110 and a differential of 23.51 or less; home or away.
A16: 46317 | B16: DET @ VAN | C16: DET | D16: -170 | E16: 20.27 | F16: =IF(AND(G16<>"W",G16<>"L"),"",IF(G16="W",IF(D16>0,D16/100,1),IF(D16<0,D16/100,-1))) | G16: W | H16: DET 5, VAN 2 | I16: Bet the pick when it has a line from -192 to +110 and a differential of 23.51 or less; home or away.
A17: 46319 | B17: ANA @ PHI | C17: PHI | D17: -122 | E17: 16.73 | F17: =IF(AND(G17<>"W",G17<>"L"),"",IF(G17="W",IF(D17>0,D17/100,1),IF(D17<0,D17/100,-1))) | G17: L | H17: ANA 5, PHI 4 | I17: Bet the pick when it has any line up to +110 and a differential of 19.38 or less; home or away.
A18: 46319 | B18: LAK @ NJD | C18: NJD | D18: -192 | E18: 9.04 | F18: =IF(AND(G18<>"W",G18<>"L"),"",IF(G18="W",IF(D18>0,D18/100,1),IF(D18<0,D18/100,-1))) | G18: W | H18: LAK 1, NJD 3 | I18: Bet the pick when it has any line up to +110 and a differential of 19.38 or less; home or away.
A19: 46319 | B19: NYR @ OTT | C19: OTT | D19: -125 | E19: 11.62 | F19: =IF(AND(G19<>"W",G19<>"L"),"",IF(G19="W",IF(D19>0,D19/100,1),IF(D19<0,D19/100,-1))) | G19: W | H19: NYR 4, OTT 7 | I19: Bet the pick when it has any line up to +110 and a differential of 19.38 or less; home or away.
A20: 46319 | B20: BUF @ WSH | C20: WSH | D20: -125 | E20: 7.47 | F20: =IF(AND(G20<>"W",G20<>"L"),"",IF(G20="W",IF(D20>0,D20/100,1),IF(D20<0,D20/100,-1))) | G20: W | H20: BUF 3, WSH 4 | I20: Bet the pick when it has any line up to +110 and a differential of 19.38 or less; home or away.
... A35: 46325 | B35: WPG @ FLA | C35: FLA | D35: -225 | E35: 20.86 | F35: =IF(AND(G35<>"W",G35<>"L"),"",IF(G35="W",IF(D35>0,D35/100,1),IF(D35<0,D35/100,-1))) | G35: W | H35: WPG 2, FLA 5 | I35: Bet the pick when it has any line up to +136 and a differential of 31.34 or less; home picks only.

Sheet 2026-27
A1: Team score betting system, NHL 2026-27 (from Oct 6, 2026)
A2: Pick the team with the higher team score in its previous game. Updated every morning and before each day's games. See the Notes tab.
A3: Today's rule: Bet the pick when it has any line up to +136 and a differential of 20.86 or less; home picks only.
A4: Total units | C4: Win % | E4: Record | G4: Bets
A5: =SUM(H9:H191) | C5: =IFERROR(COUNTIF(I9:I191,"W")/(COUNTIF(I9:I191,"W")+COUNTIF(I9:I191,"L")),"") | E5: =COUNTIF(I9:I191,"W")&"-"&COUNTIF(I9:I191,"L") | G5: =COUNTIF(I9:I191,"W")+COUNTIF(I9:I191,"L")
A8: Date | B8: Matchup | C8: Away team score | D8: Home team score | E8: Differential | F8: Pick | G8: Line | H8: Units | I8: Result | J8: Final score | K8: Line source | L8: Fits that day's rule
A9: 46301 | B9: NSH @ TOR | C9: 71.65 | D9: 68.85 | E9: =IF(OR(C9="",D9=""),"",ABS(C9-D9)) | F9: NSH | G9: 140 | H9: =IF(OR(F9="",G9="",AND(I9<>"W",I9<>"L")),"",IF(I9="W",IF(G9>0,G9/100,1),IF(G9<0,G9/100,-1))) | I9: L | J9: NSH 4, TOR 5 | K9: DraftKings closing
A10: 46301 | B10: CAR @ MTL | C10: 86.17 | D10: 72.05 | E10: =IF(OR(C10="",D10=""),"",ABS(C10-D10)) | F10: CAR | G10: -130 | H10: =IF(OR(F10="",G10="",AND(I10<>"W",I10<>"L")),"",IF(I10="W",IF(G10>0,G10/100,1),IF(G10<0,G10/100,-1))) | I10: W | J10: CAR 6, MTL 4 | K10: DraftKings closing
A11: 46301 | B11: OTT @ DET | C11: 84.73 | D11: 73.77 | E11: =IF(OR(C11="",D11=""),"",ABS(C11-D11)) | F11: OTT | G11: 110 | H11: =IF(OR(F11="",G11="",AND(I11<>"W",I11<>"L")),"",IF(I11="W",IF(G11>0,G11/100,1),IF(G11<0,G11/100,-1))) | I11: L | J11: OTT 3, DET 5 | K11: DraftKings closing
A12: 46301 | B12: UTA @ NJD | C12: 73.4 | D12: 58.64 | E12: =IF(OR(C12="",D12=""),"",ABS(C12-D12)) | F12: UTA | G12: 105 | H12: =IF(OR(F12="",G12="",AND(I12<>"W",I12<>"L")),"",IF(I12="W",IF(G12>0,G12/100,1),IF(G12<0,G12/100,-1))) | I12: W | J12: UTA 5, NJD 3 | K12: DraftKings closing
A13: 46301 | B13: MIN @ BUF | C13: 75.03 | D13: 82.04 | E13: =IF(OR(C13="",D13=""),"",ABS(C13-D13)) | F13: BUF | G13: -108 | H13: =IF(OR(F13="",G13="",AND(I13<>"W",I13<>"L")),"",IF(I13="W",IF(G13>0,G13/100,1),IF(G13<0,G13/100,-1))) | I13: W | J13: MIN 2, BUF 3 | K13: DraftKings closing
A14: 46301 | B14: NYI @ NYR | C14: 81.36 | D14: 66.6 | E14: =IF(OR(C14="",D14=""),"",ABS(C14-D14)) | F14: NYI | G14: 136 | H14: =IF(OR(F14="",G14="",AND(I14<>"W",I14<>"L")),"",IF(I14="W",IF(G14>0,G14/100,1),IF(G14<0,G14/100,-1))) | I14: L | J14: NYI 2, NYR 5 | K14: DraftKings closing
A15: 46301 | B15: STL @ CHI | C15: 48.37 | D15: 57.96 | E15: =IF(OR(C15="",D15=""),"",ABS(C15-D15)) | F15: CHI | G15: 124 | H15: =IF(OR(F15="",G15="",AND(I15<>"W",I15<>"L")),"",IF(I15="W",IF(G15>0,G15/100,1),IF(G15<0,G15/100,-1))) | I15: W | J15: STL 2, CHI 4 | K15: DraftKings closing
A16: 46301 | B16: VGK @ SEA | C16: 83.02 | D16: 80.59 | E16: =IF(OR(C16="",D16=""),"",ABS(C16-D16)) | F16: VGK | G16: -166 | H16: =IF(OR(F16="",G16="",AND(I16<>"W",I16<>"L")),"",IF(I16="W",IF(G16>0,G16/100,1),IF(G16<0,G16/100,-1))) | I16: W | J16: VGK 6, SEA 2 | K16: DraftKings closing
A17: 46301 | B17: FLA @ LAK | C17: 74.5 | D17: 75.57 | E17: =IF(OR(C17="",D17=""),"",ABS(C17-D17)) | F17: LAK | G17: -102 | H17: =IF(OR(F17="",G17="",AND(I17<>"W",I17<>"L")),"",IF(I17="W",IF(G17>0,G17/100,1),IF(G17<0,G17/100,-1))) | I17: L | J17: FLA 2, LAK 1 | K17: DraftKings closing
A18: 46302 | B18: PIT @ WSH | C18: 67.8 | D18: 61.44 | E18: =IF(OR(C18="",D18=""),"",ABS(C18-D18)) | F18: PIT | G18: 130 | H18: =IF(OR(F18="",G18="",AND(I18<>"W",I18<>"L")),"",IF(I18="W",IF(G18>0,G18/100,1),IF(G18<0,G18/100,-1))) | I18: L | J18: PIT 3, WSH 5 | K18: DraftKings closing
A19: 46302 | B19: COL @ WPG | C19: 91.63 | D19: 72.2 | E19: =IF(OR(C19="",D19=""),"",ABS(C19-D19)) | F19: COL | G19: -198 | H19: =IF(OR(F19="",G19="",AND(I19<>"W",I19<>"L")),"",IF(I19="W",IF(G19>0,G19/100,1),IF(G19<0,G19/100,-1))) | I19: L | J19: COL 2, WPG 3 | K19: DraftKings closing
A20: 46302 | B20: EDM @ ANA | C20: 80.11 | D20: 65.5 | E20: =IF(OR(C20="",D20=""),"",ABS(C20-D20)) | F20: EDM | G20: -135 | H20: =IF(OR(F20="",G20="",AND(I20<>"W",I20<>"L")),"",IF(I20="W",IF(G20>0,G20/100,1),IF(G20<0,G20/100,-1))) | I20: W | J20: EDM 5, ANA 2 | K20: DraftKings closing
... A118: 46316 | B118: FLA @ OTT | C118: 99.62 | D118: 69.39 | E118: =IF(OR(C118="",D118=""),"",ABS(C118-D118)) | F118: FLA | G118: -110 | H118: =IF(OR(F118="",G118="",AND(I118<>"W",I118<>"L")),"",IF(I118="W",IF(G118>0,G118/100,1),IF(G118<0,G118/100,-1))) | I118: L | J118: FLA 1, OTT 5 | K118: DraftKings closing (missed the pick-time run)
A119: 46317 | B119: NSH @ BOS | C119: 77.23 | D119: 59.78 | E119: =IF(OR(C119="",D119=""),"",ABS(C119-D119)) | F119: NSH | G119: 130 | H119: =IF(OR(F119="",G119="",AND(I119<>"W",I119<>"L")),"",IF(I119="W",IF(G119>0,G119/100,1),IF(G119<0,G119/100,-1))) | I119: L | J119: NSH 0, BOS 6 | K119: DraftKings at pick time (4:00 PM CT) | L119: No
A120: 46317 | B120: NYR @ TOR | C120: 82.51 | D120: 76.68 | E120: =IF(OR(C120="",D120=""),"",ABS(C120-D120)) | F120: NYR | G120: -112 | H120: =IF(OR(F120="",G120="",AND(I120<>"W",I120<>"L")),"",IF(I120="W",IF(G120>0,G120/100,1),IF(G120<0,G120/100,-1))) | I120: L | J120: NYR 4, TOR 5 | K120: DraftKings at pick time (4:00 PM CT) | L120: Yes
A121: 46317 | B121: SJS @ OTT | C121: 63.19 | D121: 86.05 | E121: =IF(OR(C121="",D121=""),"",ABS(C121-D121)) | F121: OTT | G121: -135 | H121: =IF(OR(F121="",G121="",AND(I121<>"W",I121<>"L")),"",IF(I121="W",IF(G121>0,G121/100,1),IF(G121<0,G121/100,-1))) | I121: L | J121: SJS 6, OTT 2 | K121: DraftKings at pick time (4:00 PM CT) | L121: Yes
A122: 46317 | B122: ANA @ NJD | C122: 54.31 | D122: 70.5 | E122: =IF(OR(C122="",D122=""),"",ABS(C122-D122)) | F122: NJD | G122: -218 | H122: =IF(OR(F122="",G122="",AND(I122<>"W",I122<>"L")),"",IF(I122="W",IF(G122>0,G122/100,1),IF(G122<0,G122/100,-1))) | I122: W | J122: ANA 1, NJD 4 | K122: DraftKings at pick time (4:00 PM CT) | L122: No
A123: 46317 | B123: FLA @ PIT | C123: 53.95 | D123: 58.91 | E123: =IF(OR(C123="",D123=""),"",ABS(C123-D123)) | F123: PIT | G123: -108 | H123: =IF(OR(F123="",G123="",AND(I123<>"W",I123<>"L")),"",IF(I123="W",IF(G123>0,G123/100,1),IF(G123<0,G123/100,-1))) | I123: W | J123: FLA 0, PIT 4 | K123: DraftKings at pick time (4:00 PM CT) | L123: Yes
A124: 46317 | B124: LAK @ NYI | C124: 68.72 | D124: 85.69 | E124: =IF(OR(C124="",D124=""),"",ABS(C124-D124)) | F124: NYI | G124: -105 | H124: =IF(OR(F124="",G124="",AND(I124<>"W",I124<>"L")),"",IF(I124="W",IF(G124>0,G124/100,1),IF(G124<0,G124/100,-1))) | I124: L | J124: LAK 3, NYI 2 | K124: DraftKings at pick time (4:00 PM CT) | L124: Yes
A125: 46317 | B125: VGK @ STL | C125: 58.52 | D125: 71.54 | E125: =IF(OR(C125="",D125=""),"",ABS(C125-D125)) | F125: STL | G125: 110 | H125: =IF(OR(F125="",G125="",AND(I125<>"W",I125<>"L")),"",IF(I125="W",IF(G125>0,G125/100,1),IF(G125<0,G125/100,-1))) | I125: W | J125: VGK 2, STL 6 | K125: DraftKings at pick time (4:00 PM CT) | L125: Yes
A126: 46317 | B126: WPG @ DAL | C126: 68.46 | D126: 80.22 | E126: =IF(OR(C126="",D126=""),"",ABS(C126-D126)) | F126: DAL | G126: -205 | H126: =IF(OR(F126="",G126="",AND(I126<>"W",I126<>"L")),"",IF(I126="W",IF(G126>0,G126/100,1),IF(G126<0,G126/100,-1))) | I126: W | J126: WPG 2, DAL 3 | K126: DraftKings at pick time (4:00 PM CT) | L126: No
A127: 46317 | B127: MIN @ CGY | C127: 71.28 | D127: 63.1 | E127: =IF(OR(C127="",D127=""),"",ABS(C127-D127)) | F127: MIN | G127: -205 | H127: =IF(OR(F127="",G127="",AND(I127<>"W",I127<>"L")),"",IF(I127="W",IF(G127>0,G127/100,1),IF(G127<0,G127/100,-1))) | I127: L | J127: MIN 1, CGY 2 | K127: DraftKings at pick time (4:00 PM CT) | L127: No
A128: 46317 | B128: CAR @ EDM | C128: 88.15 | D128: 68.72 | E128: =IF(OR(C128="",D128=""),"",ABS(C128-D128)) | F128: CAR | G128: -118 | H128: =IF(OR(F128="",G128="",AND(I128<>"W",I128<>"L")),"",IF(I128="W",IF(G128>0,G128/100,1),IF(G128<0,G128/100,-1))) | I128: L | J128: CAR 5, EDM 6 | K128: DraftKings at pick time (4:00 PM CT) | L128: Yes
A129: 46317 | B129: UTA @ SEA | C129: 81.09 | D129: 67.88 | E129: =IF(OR(C129="",D129=""),"",ABS(C129-D129)) | F129: UTA | G129: -170 | H129: =IF(OR(F129="",G129="",AND(I129<>"W",I129<>"L")),"",IF(I129="W",IF(G129>0,G129/100,1),IF(G129<0,G129/100,-1))) | I129: L | J129: UTA 3, SEA 5 | K129: DraftKings at pick time (4:00 PM CT) | L129: Yes
A130: 46317 | B130: DET @ VAN | C130: 72.12 | D130: 51.85 | E130: =IF(OR(C130="",D130=""),"",ABS(C130-D130)) | F130: DET | G130: -170 | H130: =IF(OR(F130="",G130="",AND(I130<>"W",I130<>"L")),"",IF(I130="W",IF(G130>0,G130/100,1),IF(G130<0,G130/100,-1))) | I130: W | J130: DET 5, VAN 2 | K130: DraftKings at pick time (4:00 PM CT) | L130: Yes
A131: 46318 | B131: MTL @ CHI | C131: 76.81 | D131: 54.49 | E131: =IF(OR(C131="",D131=""),"",ABS(C131-D131)) | F131: MTL | H131: =IF(OR(F131="",G131="",AND(I131<>"W",I131<>"L")),"",IF(I131="W",IF(G131>0,G131/100,1),IF(G131<0,G131/100,-1))) | I131: W | J131: MTL 4, CHI 1 | K131: no line at pick time | L131: No
A132: 46318 | B132: TBL @ COL | C132: 81.48 | D132: 69.5 | E132: =IF(OR(C132="",D132=""),"",ABS(C132-D132)) | F132: TBL | H132: =IF(OR(F132="",G132="",AND(I132<>"W",I132<>"L")),"",IF(I132="W",IF(G132>0,G132/100,1),IF(G132<0,G132/100,-1))) | I132: L | J132: TBL 3, COL 6 | K132: no line at pick time | L132: No
A133: 46319 | B133: ANA @ PHI | C133: 59.46 | D133: 76.19 | E133: =IF(OR(C133="",D133=""),"",ABS(C133-D133)) | F133: PHI | G133: -122 | H133: =IF(OR(F133="",G133="",AND(I133<>"W",I133<>"L")),"",IF(I133="W",IF(G133>0,G133/100,1),IF(G133<0,G133/100,-1))) | I133: L | J133: ANA 5, PHI 4 | K133: DraftKings at pick time (10:00 AM CT) | L133: Yes
A134: 46319 | B134: LAK @ NJD | C134: 71.5 | D134: 80.54 | E134: =IF(OR(C134="",D134=""),"",ABS(C134-D134)) | F134: NJD | G134: -192 | H134: =IF(OR(F134="",G134="",AND(I134<>"W",I134<>"L")),"",IF(I134="W",IF(G134>0,G134/100,1),IF(G134<0,G134/100,-1))) | I134: W | J134: LAK 1, NJD 3 | K134: DraftKings at pick time (10:00 AM CT) | L134: Yes
A135: 46319 | B135: SJS @ BOS | C135: 64.26 | D135: 91.76 | E135: =IF(OR(C135="",D135=""),"",ABS(C135-D135)) | F135: BOS | G135: -192 | H135: =IF(OR(F135="",G135="",AND(I135<>"W",I135<>"L")),"",IF(I135="W",IF(G135>0,G135/100,1),IF(G135<0,G135/100,-1))) | I135: W | J135: SJS 4, BOS 6 | K135: DraftKings at pick time (10:00 AM CT) | L135: No
A136: 46319 | B136: NYR @ OTT | C136: 64.12 | D136: 75.74 | E136: =IF(OR(C136="",D136=""),"",ABS(C136-D136)) | F136: OTT | G136: -125 | H136: =IF(OR(F136="",G136="",AND(I136<>"W",I136<>"L")),"",IF(I136="W",IF(G136>0,G136/100,1),IF(G136<0,G136/100,-1))) | I136: W | J136: NYR 4, OTT 7 | K136: DraftKings at pick time (10:00 AM CT) | L136: Yes
A137: 46319 | B137: NSH @ PIT | C137: 48.24 | D137: 79.58 | E137: =IF(OR(C137="",D137=""),"",ABS(C137-D137)) | F137: PIT | G137: -142 | H137: =IF(OR(F137="",G137="",AND(I137<>"W",I137<>"L")),"",IF(I137="W",IF(G137>0,G137/100,1),IF(G137<0,G137/100,-1))) | I137: W | J137: NSH 2, PIT 3 | K137: DraftKings at pick time (10:00 AM CT) | L137: No
A138: 46319 | B138: BUF @ WSH | C138: 63.81 | D138: 71.28 | E138: =IF(OR(C138="",D138=""),"",ABS(C138-D138)) | F138: WSH | G138: -125 | H138: =IF(OR(F138="",G138="",AND(I138<>"W",I138<>"L")),"",IF(I138="W",IF(G138>0,G138/100,1),IF(G138<0,G138/100,-1))) | I138: W | J138: BUF 3, WSH 4 | K138: DraftKings at pick time (10:00 AM CT) | L138: Yes
A139: 46319 | B139: VGK @ CBJ | C139: 60.92 | D139: 63.32 | E139: =IF(OR(C139="",D139=""),"",ABS(C139-D139)) | F139: CBJ | G139: 120 | H139: =IF(OR(F139="",G139="",AND(I139<>"W",I139<>"L")),"",IF(I139="W",IF(G139>0,G139/100,1),IF(G139<0,G139/100,-1))) | I139: W | J139: VGK 1, CBJ 2 | K139: DraftKings at pick time (10:00 AM CT) | L139: No
...

Sheet Daily rule
A1: Each day's rule: the one that would have made the most units this season up to that morning
A3: Date | B3: Rule | C3: That rule, season to date | D3: Every pick, season to date | E3: Picks emailed | F3: Their record | G3: Their units
A4: 46316 | B4: Bet the pick when it has a line from -192 to +110 and a differential of 23.51 or less; home or away. | C4: 46-18, +23.02 units | D4: 66-42, +11.47 units | E4: =COUNTIFS('Dynamic Bet Results'!$A$9:$A$5000,A4) | F4: =COUNTIFS('Dynamic Bet Results'!$A$9:$A$5000,A4,'Dynamic Bet Results'!$G$9:$G$5000,"W")&"-"&COUNTIFS('Dynamic Bet Results'!$A$9:$A$5000,A4,'Dynamic Bet Results'!$G$9:$G$5000,"L") | G4: =SUMIFS('Dynamic Bet Results'!$F$9:$F$5000,'Dynamic Bet Results'!$A$9:$A$5000,A4)
A5: 46317 | B5: Bet the pick when it has a line from -192 to +110 and a differential of 23.51 or less; home or away. | C5: 46-18, +23.02 units | D5: 67-43, +12.17 units | E5: =COUNTIFS('Dynamic Bet Results'!$A$9:$A$5000,A5) | F5: =COUNTIFS('Dynamic Bet Results'!$A$9:$A$5000,A5,'Dynamic Bet Results'!$G$9:$G$5000,"W")&"-"&COUNTIFS('Dynamic Bet Results'!$A$9:$A$5000,A5,'Dynamic Bet Results'!$G$9:$G$5000,"L") | G5: =SUMIFS('Dynamic Bet Results'!$F$9:$F$5000,'Dynamic Bet Results'!$A$9:$A$5000,A5)
A6: 46318 | B6: Bet the pick when it has any line up to +110 and a differential of 19.38 or less; home or away. | C6: 54-23, +20.97 units | D6: 72-50, +7.82 units | E6: =COUNTIFS('Dynamic Bet Results'!$A$9:$A$5000,A6) | F6: =COUNTIFS('Dynamic Bet Results'!$A$9:$A$5000,A6,'Dynamic Bet Results'!$G$9:$G$5000,"W")&"-"&COUNTIFS('Dynamic Bet Results'!$A$9:$A$5000,A6,'Dynamic Bet Results'!$G$9:$G$5000,"L") | G6: =SUMIFS('Dynamic Bet Results'!$F$9:$F$5000,'Dynamic Bet Results'!$A$9:$A$5000,A6)
A7: 46319 | B7: Bet the pick when it has any line up to +110 and a differential of 19.38 or less; home or away. | C7: 54-23, +20.97 units | D7: 72-50, +7.82 units | E7: =COUNTIFS('Dynamic Bet Results'!$A$9:$A$5000,A7) | F7: =COUNTIFS('Dynamic Bet Results'!$A$9:$A$5000,A7,'Dynamic Bet Results'!$G$9:$G$5000,"W")&"-"&COUNTIFS('Dynamic Bet Results'!$A$9:$A$5000,A7,'Dynamic Bet Results'!$G$9:$G$5000,"L") | G7: =SUMIFS('Dynamic Bet Results'!$F$9:$F$5000,'Dynamic Bet Results'!$A$9:$A$5000,A7)
A8: 46320 | B8: Bet the pick when it has a line from -198 to +150 and a differential of 14.61 or less; home or away. | C8: 48-19, +27.21 units | D8: 81-53, +13.82 units | E8: =COUNTIFS('Dynamic Bet Results'!$A$9:$A$5000,A8) | F8: =COUNTIFS('Dynamic Bet Results'!$A$9:$A$5000,A8,'Dynamic Bet Results'!$G$9:$G$5000,"W")&"-"&COUNTIFS('Dynamic Bet Results'!$A$9:$A$5000,A8,'Dynamic Bet Results'!$G$9:$G$5000,"L") | G8: =SUMIFS('Dynamic Bet Results'!$F$9:$F$5000,'Dynamic Bet Results'!$A$9:$A$5000,A8)
A9: 46321 | B9: Bet the pick when it has a line from -198 to +150 and a differential of 14.61 or less; home or away. | C9: 50-19, +29.21 units | D9: 85-54, +15.52 units | E9: =COUNTIFS('Dynamic Bet Results'!$A$9:$A$5000,A9) | F9: =COUNTIFS('Dynamic Bet Results'!$A$9:$A$5000,A9,'Dynamic Bet Results'!$G$9:$G$5000,"W")&"-"&COUNTIFS('Dynamic Bet Results'!$A$9:$A$5000,A9,'Dynamic Bet Results'!$G$9:$G$5000,"L") | G9: =SUMIFS('Dynamic Bet Results'!$F$9:$F$5000,'Dynamic Bet Results'!$A$9:$A$5000,A9)
A10: 46322 | B10: Bet the pick when it has a line from -198 to +150 and a differential of 14.61 or less; home or away. | C10: 51-21, +28.01 units | D10: 86-56, +14.32 units | E10: =COUNTIFS('Dynamic Bet Results'!$A$9:$A$5000,A10) | F10: =COUNTIFS('Dynamic Bet Results'!$A$9:$A$5000,A10,'Dynamic Bet Results'!$G$9:$G$5000,"W")&"-"&COUNTIFS('Dynamic Bet Results'!$A$9:$A$5000,A10,'Dynamic Bet Results'!$G$9:$G$5000,"L") | G10: =SUMIFS('Dynamic Bet Results'!$F$9:$F$5000,'Dynamic Bet Results'!$A$9:$A$5000,A10)
A11: 46323 | B11: Bet the pick when it has a line from -198 to +150 and a differential of 14.61 or less; home or away. | C11: 51-21, +28.01 units | D11: 86-56, +14.32 units | E11: =COUNTIFS('Dynamic Bet Results'!$A$9:$A$5000,A11) | F11: =COUNTIFS('Dynamic Bet Results'!$A$9:$A$5000,A11,'Dynamic Bet Results'!$G$9:$G$5000,"W")&"-"&COUNTIFS('Dynamic Bet Results'!$A$9:$A$5000,A11,'Dynamic Bet Results'!$G$9:$G$5000,"L") | G11: =SUMIFS('Dynamic Bet Results'!$F$9:$F$5000,'Dynamic Bet Results'!$A$9:$A$5000,A11)
A12: 46324 | B12: Bet the pick when it has a line from -198 to +150 and a differential of 14.61 or less; home or away. | C12: 51-23, +25.66 units | D12: 87-59, +11.97 units | E12: =COUNTIFS('Dynamic Bet Results'!$A$9:$A$5000,A12) | F12: =COUNTIFS('Dynamic Bet Results'!$A$9:$A$5000,A12,'Dynamic Bet Results'!$G$9:$G$5000,"W")&"-"&COUNTIFS('Dynamic Bet Results'!$A$9:$A$5000,A12,'Dynamic Bet Results'!$G$9:$G$5000,"L") | G12: =SUMIFS('Dynamic Bet Results'!$F$9:$F$5000,'Dynamic Bet Results'!$A$9:$A$5000,A12)
A13: 46325 | B13: Bet the pick when it has any line up to +136 and a differential of 31.34 or less; home picks only. | C13: 51-19, +23.89 units | D13: 93-64, +12.25 units | E13: =COUNTIFS('Dynamic Bet Results'!$A$9:$A$5000,A13) | F13: =COUNTIFS('Dynamic Bet Results'!$A$9:$A$5000,A13,'Dynamic Bet Results'!$G$9:$G$5000,"W")&"-"&COUNTIFS('Dynamic Bet Results'!$A$9:$A$5000,A13,'Dynamic Bet Results'!$G$9:$G$5000,"L") | G13: =SUMIFS('Dynamic Bet Results'!$F$9:$F$5000,'Dynamic Bet Results'!$A$9:$A$5000,A13)
A14: 46326 | B14: Bet the pick when it has any line up to +136 and a differential of 20.86 or less; home picks only. | C14: 46-16, +24.04 units | D14: 94-66, +10.95 units | E14: =COUNTIFS('Dynamic Bet Results'!$A$9:$A$5000,A14) | F14: =COUNTIFS('Dynamic Bet Results'!$A$9:$A$5000,A14,'Dynamic Bet Results'!$G$9:$G$5000,"W")&"-"&COUNTIFS('Dynamic Bet Results'!$A$9:$A$5000,A14,'Dynamic Bet Results'!$G$9:$G$5000,"L") | G14: =SUMIFS('Dynamic Bet Results'!$F$9:$F$5000,'Dynamic Bet Results'!$A$9:$A$5000,A14)

Sheet 2025-26
A1: Team score betting backtest, NHL 2025-26 regular season (from Oct 14, 2025)
A2: Pick the team with the higher team score in its previous game; bet the closing moneyline. See the Notes tab.
A4: Total units | C4: Win % | E4: Record | G4: Bets
A5: =SUM(H9:H1272) | C5: =IFERROR(COUNTIF(I9:I1272,"W")/(COUNTIF(I9:I1272,"W")+COUNTIF(I9:I1272,"L")),"") | E5: =COUNTIF(I9:I1272,"W")&"-"&COUNTIF(I9:I1272,"L") | G5: =COUNTIF(I9:I1272,"W")+COUNTIF(I9:I1272,"L")
A8: Date | B8: Matchup | C8: Away team score | D8: Home team score | E8: Differential | F8: Pick | G8: Line | H8: Units | I8: Result | J8: Final score | K8: Line source
A9: 45944 | B9: NSH @ TOR | C9: 70.16 | D9: 76.41 | E9: =IF(OR(C9="",D9=""),"",ABS(C9-D9)) | F9: TOR | G9: -175 | H9: =IF(OR(F9="",G9="",AND(I9<>"W",I9<>"L")),"",IF(I9="W",IF(G9>0,G9/100,1),IF(G9<0,G9/100,-1))) | I9: W | J9: NSH 4, TOR 7 | K9: ESPN BET closing
A10: 45944 | B10: SEA @ MTL | C10: 70.93 | D10: 76.95 | E10: =IF(OR(C10="",D10=""),"",ABS(C10-D10)) | F10: MTL | G10: -155 | H10: =IF(OR(F10="",G10="",AND(I10<>"W",I10<>"L")),"",IF(I10="W",IF(G10>0,G10/100,1),IF(G10<0,G10/100,-1))) | I10: W | J10: SEA 4, MTL 5 | K10: ESPN BET closing
A11: 45944 | B11: EDM @ NYR | C11: 82.17 | D11: 71.78 | E11: =IF(OR(C11="",D11=""),"",ABS(C11-D11)) | F11: EDM | G11: -135 | H11: =IF(OR(F11="",G11="",AND(I11<>"W",I11<>"L")),"",IF(I11="W",IF(G11>0,G11/100,1),IF(G11<0,G11/100,-1))) | I11: W | J11: EDM 2, NYR 0 | K11: ESPN BET closing
A12: 45944 | B12: TBL @ WSH | C12: 77.61 | D12: 68.22 | E12: =IF(OR(C12="",D12=""),"",ABS(C12-D12)) | F12: TBL | G12: -115 | H12: =IF(OR(F12="",G12="",AND(I12<>"W",I12<>"L")),"",IF(I12="W",IF(G12>0,G12/100,1),IF(G12<0,G12/100,-1))) | I12: L | J12: TBL 2, WSH 3 | K12: ESPN BET closing
A13: 45944 | B13: VGK @ CGY | C13: 69.07 | D13: 66.53 | E13: =IF(OR(C13="",D13=""),"",ABS(C13-D13)) | F13: VGK | G13: -170 | H13: =IF(OR(F13="",G13="",AND(I13<>"W",I13<>"L")),"",IF(I13="W",IF(G13>0,G13/100,1),IF(G13<0,G13/100,-1))) | I13: W | J13: VGK 4, CGY 2 | K13: ESPN BET closing
A14: 45944 | B14: MIN @ DAL | C14: 65.34 | D14: 58 | E14: =IF(OR(C14="",D14=""),"",ABS(C14-D14)) | F14: MIN | G14: 160 | H14: =IF(OR(F14="",G14="",AND(I14<>"W",I14<>"L")),"",IF(I14="W",IF(G14>0,G14/100,1),IF(G14<0,G14/100,-1))) | I14: L | J14: MIN 2, DAL 5 | K14: ESPN BET closing
A15: 45944 | B15: CAR @ SJS | C15: 82.44 | D15: 54.08 | E15: =IF(OR(C15="",D15=""),"",ABS(C15-D15)) | F15: CAR | G15: -260 | H15: =IF(OR(F15="",G15="",AND(I15<>"W",I15<>"L")),"",IF(I15="W",IF(G15>0,G15/100,1),IF(G15<0,G15/100,-1))) | I15: W | J15: CAR 5, SJS 1 | K15: ESPN BET closing
A16: 45944 | B16: PIT @ ANA | C16: 49.26 | D16: 85.92 | E16: =IF(OR(C16="",D16=""),"",ABS(C16-D16)) | F16: ANA | G16: -145 | H16: =IF(OR(F16="",G16="",AND(I16<>"W",I16<>"L")),"",IF(I16="W",IF(G16>0,G16/100,1),IF(G16<0,G16/100,-1))) | I16: W | J16: PIT 3, ANA 4 | K16: ESPN BET closing
A17: 45945 | B17: OTT @ BUF | C17: 69.84 | D17: 61.84 | E17: =IF(OR(C17="",D17=""),"",ABS(C17-D17)) | F17: OTT | G17: -120 | H17: =IF(OR(F17="",G17="",AND(I17<>"W",I17<>"L")),"",IF(I17="W",IF(G17>0,G17/100,1),IF(G17<0,G17/100,-1))) | I17: L | J17: OTT 4, BUF 8 | K17: ESPN BET closing
A18: 45945 | B18: FLA @ DET | C18: 64.84 | D18: 63.59 | E18: =IF(OR(C18="",D18=""),"",ABS(C18-D18)) | F18: FLA | G18: -155 | H18: =IF(OR(F18="",G18="",AND(I18<>"W",I18<>"L")),"",IF(I18="W",IF(G18>0,G18/100,1),IF(G18<0,G18/100,-1))) | I18: L | J18: FLA 1, DET 4 | K18: ESPN BET closing
A19: 45945 | B19: CHI @ STL | C19: 64.34 | D19: 81.44 | E19: =IF(OR(C19="",D19=""),"",ABS(C19-D19)) | F19: STL | G19: -240 | H19: =IF(OR(F19="",G19="",AND(I19<>"W",I19<>"L")),"",IF(I19="W",IF(G19>0,G19/100,1),IF(G19<0,G19/100,-1))) | I19: L | J19: CHI 8, STL 3 | K19: ESPN BET closing
A20: 45945 | B20: CGY @ UTA | C20: 65.9 | D20: 75.66 | E20: =IF(OR(C20="",D20=""),"",ABS(C20-D20)) | F20: UTA | G20: -240 | H20: =IF(OR(F20="",G20="",AND(I20<>"W",I20<>"L")),"",IF(I20="W",IF(G20>0,G20/100,1),IF(G20<0,G20/100,-1))) | I20: W | J20: CGY 1, UTA 3 | K20: ESPN BET closing
... A862: 46058 | B862: PIT @ BUF | C862: 76.65 | D862: 61.49 | E862: =IF(OR(C862="",D862=""),"",ABS(C862-D862)) | F862: PIT | G862: 105 | H862: =IF(OR(F862="",G862="",AND(I862<>"W",I862<>"L")),"",IF(I862="W",IF(G862>0,G862/100,1),IF(G862<0,G862/100,-1))) | I862: W | J862: PIT 5, BUF 2 | K862: DraftKings closing
A863: 46058 | B863: NYI @ NJD | C863: 63.35 | D863: 63.35 | E863: =IF(OR(C863="",D863=""),"",ABS(C863-D863)) | H863: =IF(OR(F863="",G863="",AND(I863<>"W",I863<>"L")),"",IF(I863="W",IF(G863>0,G863/100,1),IF(G863<0,G863/100,-1))) | J863: NYI 3, NJD 1
A864: 46058 | B864: CAR @ NYR | C864: 68.88 | D864: 62.26 | E864: =IF(OR(C864="",D864=""),"",ABS(C864-D864)) | F864: CAR | G864: -225 | H864: =IF(OR(F864="",G864="",AND(I864<>"W",I864<>"L")),"",IF(I864="W",IF(G864>0,G864/100,1),IF(G864<0,G864/100,-1))) | I864: W | J864: CAR 2, NYR 0 | K864: DraftKings closing
A865: 46058 | B865: OTT @ PHI | C865: 71.12 | D865: 70.38 | E865: =IF(OR(C865="",D865=""),"",ABS(C865-D865)) | F865: OTT | G865: -130 | H865: =IF(OR(F865="",G865="",AND(I865<>"W",I865<>"L")),"",IF(I865="W",IF(G865>0,G865/100,1),IF(G865<0,G865/100,-1))) | I865: W | J865: OTT 2, PHI 1 | K865: DraftKings closing
A866: 46058 | B866: NSH @ WSH | C866: 60.13 | D866: 69.62 | E866: =IF(OR(C866="",D866=""),"",ABS(C866-D866)) | F866: WSH | G866: -175 | H866: =IF(OR(F866="",G866="",AND(I866<>"W",I866<>"L")),"",IF(I866="W",IF(G866>0,G866/100,1),IF(G866<0,G866/100,-1))) | I866: W | J866: NSH 2, WSH 4 | K866: DraftKings closing
A867: 46058 | B867: FLA @ TBL | C867: 70.25 | D867: 78.51 | E867: =IF(OR(C867="",D867=""),"",ABS(C867-D867)) | F867: TBL | G867: -218 | H867: =IF(OR(F867="",G867="",AND(I867<>"W",I867<>"L")),"",IF(I867="W",IF(G867>0,G867/100,1),IF(G867<0,G867/100,-1))) | I867: W | J867: FLA 1, TBL 6 | K867: DraftKings closing
A868: 46058 | B868: LAK @ VGK | C868: 64.5 | D868: 85.26 | E868: =IF(OR(C868="",D868=""),"",ABS(C868-D868)) | F868: VGK | G868: -142 | H868: =IF(OR(F868="",G868="",AND(I868<>"W",I868<>"L")),"",IF(I868="W",IF(G868>0,G868/100,1),IF(G868<0,G868/100,-1))) | I868: W | J868: LAK 1, VGK 4 | K868: DraftKings closing
A869: 46078 | B869: BUF @ NJD | C869: 63.29 | D869: 66.62 | E869: =IF(OR(C869="",D869=""),"",ABS(C869-D869)) | F869: NJD | G869: -112 | H869: =IF(OR(F869="",G869="",AND(I869<>"W",I869<>"L")),"",IF(I869="W",IF(G869>0,G869/100,1),IF(G869<0,G869/100,-1))) | I869: L | J869: BUF 2, NJD 1 | K869: DraftKings closing
A870: 46078 | B870: PHI @ WSH | C870: 65.82 | D870: 72.06 | E870: =IF(OR(C870="",D870=""),"",ABS(C870-D870)) | F870: WSH | G870: -142 | H870: =IF(OR(F870="",G870="",AND(I870<>"W",I870<>"L")),"",IF(I870="W",IF(G870>0,G870/100,1),IF(G870<0,G870/100,-1))) | I870: W | J870: PHI 1, WSH 3 | K870: DraftKings closing
A871: 46078 | B871: TOR @ TBL | C871: 68.57 | D871: 77.99 | E871: =IF(OR(C871="",D871=""),"",ABS(C871-D871)) | F871: TBL | G871: -225 | H871: =IF(OR(F871="",G871="",AND(I871<>"W",I871<>"L")),"",IF(I871="W",IF(G871>0,G871/100,1),IF(G871<0,G871/100,-1))) | I871: W | J871: TOR 2, TBL 4 | K871: DraftKings closing
A872: 46078 | B872: SEA @ DAL | C872: 75.5 | D872: 77 | E872: =IF(OR(C872="",D872=""),"",ABS(C872-D872)) | F872: DAL | G872: -170 | H872: =IF(OR(F872="",G872="",AND(I872<>"W",I872<>"L")),"",IF(I872="W",IF(G872>0,G872/100,1),IF(G872<0,G872/100,-1))) | I872: W | J872: SEA 1, DAL 4 | K872: DraftKings closing
A873: 46078 | B873: COL @ UTA | C873: 85.64 | D873: 73.06 | E873: =IF(OR(C873="",D873=""),"",ABS(C873-D873)) | F873: COL | G873: -120 | H873: =IF(OR(F873="",G873="",AND(I873<>"W",I873<>"L")),"",IF(I873="W",IF(G873>0,G873/100,1),IF(G873<0,G873/100,-1))) | I873: W | J873: COL 4, UTA 2 | K873: DraftKings closing
A874: 46078 | B874: WPG @ VAN | C874: 67.01 | D874: 54.74 | E874: =IF(OR(C874="",D874=""),"",ABS(C874-D874)) | F874: WPG | G874: -130 | H874: =IF(OR(F874="",G874="",AND(I874<>"W",I874<>"L")),"",IF(I874="W",IF(G874>0,G874/100,1),IF(G874<0,G874/100,-1))) | I874: W | J874: WPG 3, VAN 2 | K874: DraftKings closing
A875: 46078 | B875: VGK @ LAK | C875: 76.27 | D875: 63.73 | E875: =IF(OR(C875="",D875=""),"",ABS(C875-D875)) | F875: VGK | G875: 150 | H875: =IF(OR(F875="",G875="",AND(I875<>"W",I875<>"L")),"",IF(I875="W",IF(G875>0,G875/100,1),IF(G875<0,G875/100,-1))) | I875: W | J875: VGK 6, LAK 4 | K875: DraftKings closing
... A1272: 46128 | B1272: SEA @ COL | C1272: 53.42 | D1272: 77.48 | E1272: =IF(OR(C1272="",D1272=""),"",ABS(C1272-D1272)) | F1272: COL | G1272: -218 | H1272: =IF(OR(F1272="",G1272="",AND(I1272<>"W",I1272<>"L")),"",IF(I1272="W",IF(G1272>0,G1272/100,1),IF(G1272<0,G1272/100,-1))) | I1272: W | J1272: SEA 0, COL 2 | K1272: DraftKings closing

Sheet Notes
A1: How it works
A2: System | B2: In every game, pick the team whose team score was higher in its own previous game that season.
A3: Team score | B3: The website's formula and constants (dashboard_template.html, teamScore): 70 + 2.896 x goal difference (no empty-net goals, no shootout) + 1.997 x expected goals difference + 0.294 x score-adjusted 5-on-5 shot attempt difference, kept between 0 and 100. The constants were fitted on every game of 2025-26 (all 32 teams) and aren't refitted.
A4: Units | B4: Win on a minus line = +1. Win on a plus line = line / 100 (e.g. +240 wins 2.4). Loss on a minus line = line / 100 (e.g. -240 loses 2.4). Loss on a plus line = -1. Results include overtime and the shootout.
A5: Lines | B5: From ESPN's free odds feed: DraftKings, or ESPN BET where DraftKings isn't listed. Oct 6-21, 2026 and all of 2025-26 use closing lines. From Oct 22, 2026, every game is picked 2 hours before the day's first game at the line right then, and units are graded on that line. A game without a line at that time gets its closing line, and the Line source column says so.
A6: Daily schedule | B6: Every morning after 6 am Central: last night's games are scored and graded, and the rule is reset. Two hours before the day's first game: every game is picked, this file is rebuilt and emailed.
A7: The daily rule | B7: Every rule of the form 'line from X to Y, differential from A up to B, home picks / away picks / either' is tried on every graded 2026-27 pick up to that morning, with every line and every differential seen so far as a possible cut point, and the one that would have made the most units wins (ties go to the rule with more bets). A bound at the edge of the lines seen so far is left open. 'Fits that day's rule' marks the picks it chose.
A8: Caution | B8: The daily rule is the best fit to the past by construction, so its record always looks good. The honest test is the Dynamic Bet Results tab: only the picks that were emailed under each day's rule, before their games, at the line in the email. On 2025-26, rules found this way didn't carry over from one half of the season to the other or to 2026-27.
A9: Sources | B9: Game data: NHL public API (api-web.nhle.com). Odds: ESPN public API. Updated 2026-10-31 10:00 CT.
